2024-03-08 13:23:07,551 INFO    MainThread:13417 [wandb_setup.py:_flush():76] Current SDK version is 0.16.3
2024-03-08 13:23:07,551 INFO    MainThread:13417 [wandb_setup.py:_flush():76] Configure stats pid to 13417
2024-03-08 13:23:07,551 INFO    MainThread:13417 [wandb_setup.py:_flush():76] Loading settings from /home/uosai/.config/wandb/settings
2024-03-08 13:23:07,551 INFO    MainThread:13417 [wandb_setup.py:_flush():76] Loading settings from /home/uosai/바탕화면/mini-marl/vdn/wandb/settings
2024-03-08 13:23:07,551 INFO    MainThread:13417 [wandb_setup.py:_flush():76] Loading settings from environment variables: {}
2024-03-08 13:23:07,551 INFO    MainThread:13417 [wandb_setup.py:_flush():76] Applying setup settings: {'_disable_service': False}
2024-03-08 13:23:07,551 INFO    MainThread:13417 [wandb_setup.py:_flush():76] Inferring run settings from compute environment: {'program_relpath': 'vdn/main.py', 'program_abspath': '/home/uosai/바탕화면/mini-marl/vdn/main.py', 'program': '/home/uosai/바탕화면/mini-marl/vdn/main.py'}
2024-03-08 13:23:07,551 INFO    MainThread:13417 [wandb_init.py:_log_setup():526] Logging user logs to /home/uosai/바탕화면/mini-marl/vdn/wandb/run-20240308_132307-o31xp2us/logs/debug.log
2024-03-08 13:23:07,551 INFO    MainThread:13417 [wandb_init.py:_log_setup():527] Logging internal logs to /home/uosai/바탕화면/mini-marl/vdn/wandb/run-20240308_132307-o31xp2us/logs/debug-internal.log
2024-03-08 13:23:07,551 INFO    MainThread:13417 [wandb_init.py:init():566] calling init triggers
2024-03-08 13:23:07,551 INFO    MainThread:13417 [wandb_init.py:init():573] wandb.init called with sweep_config: {}
config: {'use_wandb': True, 'entity_name': 'singforai7012', 'env_name': 'ma_gym:Checkers-v0', 'experiment_name': 'junk', 'use_cuda': False, 'n_training_threads': 12, 'use_render': False, 'use_time_sleep': False, 'sleep_second': 0.5, 'seed': 42, 'fix_seed': True, 'epsilon_anneal_episode': 60000, 'max_epsilon': 0.9, 'min_epsilon': 0.05, 'lr': 0.001, 'gamma': 0.99, 'batch_size': 32, 'max_episodes': 100000, 'max_step': 100, 'step_cost': -0.01, 'chunk_size': 10, 'update_iter': 10, 'update_target_interval': 20, 'grad_clip_norm': 5, 'target_setting': 'dqn', 'action_network': 'q_net', 'use_recurrent': True, 'test_interval': 10, 'test_episodes': 10, 'buffer_limit': 100, 'eps': 1e-06, 'alpha': 0.8, 'beta': 0.2, 'update_alpha_beta': True}
2024-03-08 13:23:07,551 INFO    MainThread:13417 [wandb_init.py:init():616] starting backend
2024-03-08 13:23:07,551 INFO    MainThread:13417 [wandb_init.py:init():620] setting up manager
2024-03-08 13:23:07,554 INFO    MainThread:13417 [backend.py:_multiprocessing_setup():105] multiprocessing start_methods=fork,spawn,forkserver, using: spawn
2024-03-08 13:23:07,555 INFO    MainThread:13417 [wandb_init.py:init():628] backend started and connected
2024-03-08 13:23:07,563 INFO    MainThread:13417 [wandb_init.py:init():720] updated telemetry
2024-03-08 13:23:07,580 INFO    MainThread:13417 [wandb_init.py:init():753] communicating run to backend with 90.0 second timeout
2024-03-08 13:23:07,970 ERROR   MainThread:13417 [wandb_init.py:init():779] encountered error: It appears that you do not have permission to access the requested resource. Please reach out to the project owner to grant you access. If you have the correct permissions, verify that there are no issues with your networking setup.(Error 404: Not Found)
2024-03-08 13:23:08,045 ERROR   MainThread:13417 [wandb_init.py:init():1194] It appears that you do not have permission to access the requested resource. Please reach out to the project owner to grant you access. If you have the correct permissions, verify that there are no issues with your networking setup.(Error 404: Not Found)
Traceback (most recent call last):
  File "/home/uosai/바탕화면/miniconda3/envs/simplenv/lib/python3.9/site-packages/wandb/sdk/wandb_init.py", line 1176, in init
    run = wi.init()
  File "/home/uosai/바탕화면/miniconda3/envs/simplenv/lib/python3.9/site-packages/wandb/sdk/wandb_init.py", line 785, in init
    raise error
wandb.errors.CommError: It appears that you do not have permission to access the requested resource. Please reach out to the project owner to grant you access. If you have the correct permissions, verify that there are no issues with your networking setup.(Error 404: Not Found)
2024-03-08 13:23:09,047 WARNING MsgRouterThr:13417 [router.py:message_loop():77] message_loop has been closed
